[2022-02-04 09:35:18 +0000] [1] [INFO] Starting gunicorn 20.1.0
[2022-02-04 09:35:18 +0000] [1] [INFO] Listening at: http://0.0.0.0:8000 (1)
[2022-02-04 09:35:18 +0000] [1] [INFO] Using worker: sync
[2022-02-04 09:35:18 +0000] [12] [INFO] Booting worker with pid: 12
[2022-02-04 09:35:18 +0000] [13] [INFO] Booting worker with pid: 13
[2022-02-04 09:35:18 +0000] [14] [INFO] Booting worker with pid: 14
[2022-02-04 09:35:18 +0000] [15] [INFO] Booting worker with pid: 15
[2022-02-04 09:35:18 +0000] [12] [ERROR] Exception in worker process
Traceback (most recent call last):
  File "/usr/local/lib/python3.10/site-packages/gunicorn/arbiter.py", line 589, in spawn_worker
    worker.init_process()
  File "/usr/local/lib/python3.10/site-packages/gunicorn/workers/base.py", line 134, in init_process
    self.load_wsgi()
  File "/usr/local/lib/python3.10/site-packages/gunicorn/workers/base.py", line 146, in load_wsgi
    self.wsgi = self.app.wsgi()
  File "/usr/local/lib/python3.10/site-packages/gunicorn/app/base.py", line 67, in wsgi
    self.callable = self.load()
  File "/usr/local/lib/python3.10/site-packages/gunicorn/app/wsgiapp.py", line 58, in load
    return self.load_wsgiapp()
  File "/usr/local/lib/python3.10/site-packages/gunicorn/app/wsgiapp.py", line 48, in load_wsgiapp
    return util.import_app(self.app_uri)
  File "/usr/local/lib/python3.10/site-packages/gunicorn/util.py", line 359, in import_app
    mod = importlib.import_module(module)
  File "/usr/local/lib/python3.10/importlib/__init__.py", line 126, in import_module
    return _bootstrap._gcd_import(name[level:], package, level)
  File "<frozen importlib._bootstrap>", line 1050, in _gcd_import
  File "<frozen importlib._bootstrap>", line 1027, in _find_and_load
  File "<frozen importlib._bootstrap>", line 1006, in _find_and_load_unlocked
  File "<frozen importlib._bootstrap>", line 688, in _load_unlocked
  File "<frozen importlib._bootstrap_external>", line 883, in exec_module
  File "<frozen importlib._bootstrap>", line 241, in _call_with_frames_removed
  File "/app/SilthsSanctuary/wsgi.py", line 15, in <module>
    application = get_wsgi_application()
  File "/usr/local/lib/python3.10/site-packages/django/core/wsgi.py", line 12, in get_wsgi_application
    django.setup(set_prefix=False)
  File "/usr/local/lib/python3.10/site-packages/django/__init__.py", line 19, in setup
    configure_logging(settings.LOGGING_CONFIG, settings.LOGGING)
  File "/usr/local/lib/python3.10/site-packages/django/conf/__init__.py", line 84, in __getattr__
    self._setup(name)
  File "/usr/local/lib/python3.10/site-packages/django/conf/__init__.py", line 71, in _setup
    self._wrapped = Settings(settings_module)
  File "/usr/local/lib/python3.10/site-packages/django/conf/__init__.py", line 179, in __init__
    mod = importlib.import_module(self.SETTINGS_MODULE)
  File "/usr/local/lib/python3.10/importlib/__init__.py", line 126, in import_module
    return _bootstrap._gcd_import(name[level:], package, level)
  File "<frozen importlib._bootstrap>", line 1050, in _gcd_import
  File "<frozen importlib._bootstrap>", line 1027, in _find_and_load
  File "<frozen importlib._bootstrap>", line 1006, in _find_and_load_unlocked
  File "<frozen importlib._bootstrap>", line 688, in _load_unlocked
  File "<frozen importlib._bootstrap_external>", line 883, in exec_module
  File "<frozen importlib._bootstrap>", line 241, in _call_with_frames_removed
  File "/app/SilthsSanctuary/settings/local.py", line 1, in <module>
    from base import *
ModuleNotFoundError: No module named 'base'
[2022-02-04 09:35:18 +0000] [12] [INFO] Worker exiting (pid: 12)
[2022-02-04 09:35:18 +0000] [13] [ERROR] Exception in worker process
Traceback (most recent call last):
  File "/usr/local/lib/python3.10/site-packages/gunicorn/arbiter.py", line 589, in spawn_worker
    worker.init_process()
  File "/usr/local/lib/python3.10/site-packages/gunicorn/workers/base.py", line 134, in init_process
    self.load_wsgi()
  File "/usr/local/lib/python3.10/site-packages/gunicorn/workers/base.py", line 146, in load_wsgi
    self.wsgi = self.app.wsgi()
  File "/usr/local/lib/python3.10/site-packages/gunicorn/app/base.py", line 67, in wsgi
    self.callable = self.load()
  File "/usr/local/lib/python3.10/site-packages/gunicorn/app/wsgiapp.py", line 58, in load
    return self.load_wsgiapp()
  File "/usr/local/lib/python3.10/site-packages/gunicorn/app/wsgiapp.py", line 48, in load_wsgiapp
    return util.import_app(self.app_uri)
  File "/usr/local/lib/python3.10/site-packages/gunicorn/util.py", line 359, in import_app
    mod = importlib.import_module(module)
  File "/usr/local/lib/python3.10/importlib/__init__.py", line 126, in import_module
    return _bootstrap._gcd_import(name[level:], package, level)
  File "<frozen importlib._bootstrap>", line 1050, in _gcd_import
  File "<frozen importlib._bootstrap>", line 1027, in _find_and_load
  File "<frozen importlib._bootstrap>", line 1006, in _find_and_load_unlocked
  File "<frozen importlib._bootstrap>", line 688, in _load_unlocked
  File "<frozen importlib._bootstrap_external>", line 883, in exec_module
  File "<frozen importlib._bootstrap>", line 241, in _call_with_frames_removed
  File "/app/SilthsSanctuary/wsgi.py", line 15, in <module>
    application = get_wsgi_application()
  File "/usr/local/lib/python3.10/site-packages/django/core/wsgi.py", line 12, in get_wsgi_application
    django.setup(set_prefix=False)
  File "/usr/local/lib/python3.10/site-packages/django/__init__.py", line 19, in setup
    configure_logging(settings.LOGGING_CONFIG, settings.LOGGING)
  File "/usr/local/lib/python3.10/site-packages/django/conf/__init__.py", line 84, in __getattr__
    self._setup(name)
  File "/usr/local/lib/python3.10/site-packages/django/conf/__init__.py", line 71, in _setup
    self._wrapped = Settings(settings_module)
  File "/usr/local/lib/python3.10/site-packages/django/conf/__init__.py", line 179, in __init__
    mod = importlib.import_module(self.SETTINGS_MODULE)
  File "/usr/local/lib/python3.10/importlib/__init__.py", line 126, in import_module
    return _bootstrap._gcd_import(name[level:], package, level)
  File "<frozen importlib._bootstrap>", line 1050, in _gcd_import
  File "<frozen importlib._bootstrap>", line 1027, in _find_and_load
  File "<frozen importlib._bootstrap>", line 1006, in _find_and_load_unlocked
  File "<frozen importlib._bootstrap>", line 688, in _load_unlocked
  File "<frozen importlib._bootstrap_external>", line 883, in exec_module
  File "<frozen importlib._bootstrap>", line 241, in _call_with_frames_removed
  File "/app/SilthsSanctuary/settings/local.py", line 1, in <module>
    from base import *
ModuleNotFoundError: No module named 'base'
[2022-02-04 09:35:18 +0000] [13] [INFO] Worker exiting (pid: 13)
[2022-02-04 09:35:18 +0000] [1] [WARNING] Worker with pid 13 was terminated due to signal 15
[2022-02-04 09:35:18 +0000] [14] [ERROR] Exception in worker process
Traceback (most recent call last):
  File "/usr/local/lib/python3.10/site-packages/gunicorn/arbiter.py", line 589, in spawn_worker
    worker.init_process()
  File "/usr/local/lib/python3.10/site-packages/gunicorn/workers/base.py", line 134, in init_process
    self.load_wsgi()
  File "/usr/local/lib/python3.10/site-packages/gunicorn/workers/base.py", line 146, in load_wsgi
    self.wsgi = self.app.wsgi()
  File "/usr/local/lib/python3.10/site-packages/gunicorn/app/base.py", line 67, in wsgi
    self.callable = self.load()
  File "/usr/local/lib/python3.10/site-packages/gunicorn/app/wsgiapp.py", line 58, in load
    return self.load_wsgiapp()
  File "/usr/local/lib/python3.10/site-packages/gunicorn/app/wsgiapp.py", line 48, in load_wsgiapp
    return util.import_app(self.app_uri)
  File "/usr/local/lib/python3.10/site-packages/gunicorn/util.py", line 359, in import_app
    mod = importlib.import_module(module)
  File "/usr/local/lib/python3.10/importlib/__init__.py", line 126, in import_module
    return _bootstrap._gcd_import(name[level:], package, level)
  File "<frozen importlib._bootstrap>", line 1050, in _gcd_import
  File "<frozen importlib._bootstrap>", line 1027, in _find_and_load
  File "<frozen importlib._bootstrap>", line 1006, in _find_and_load_unlocked
  File "<frozen importlib._bootstrap>", line 688, in _load_unlocked
  File "<frozen importlib._bootstrap_external>", line 883, in exec_module
  File "<frozen importlib._bootstrap>", line 241, in _call_with_frames_removed
  File "/app/SilthsSanctuary/wsgi.py", line 15, in <module>
    application = get_wsgi_application()
  File "/usr/local/lib/python3.10/site-packages/django/core/wsgi.py", line 12, in get_wsgi_application
    django.setup(set_prefix=False)
  File "/usr/local/lib/python3.10/site-packages/django/__init__.py", line 19, in setup
    configure_logging(settings.LOGGING_CONFIG, settings.LOGGING)
  File "/usr/local/lib/python3.10/site-packages/django/conf/__init__.py", line 84, in __getattr__
    self._setup(name)
  File "/usr/local/lib/python3.10/site-packages/django/conf/__init__.py", line 71, in _setup
    self._wrapped = Settings(settings_module)
  File "/usr/local/lib/python3.10/site-packages/django/conf/__init__.py", line 179, in __init__
    mod = importlib.import_module(self.SETTINGS_MODULE)
  File "/usr/local/lib/python3.10/importlib/__init__.py", line 126, in import_module
    return _bootstrap._gcd_import(name[level:], package, level)
  File "<frozen importlib._bootstrap>", line 1050, in _gcd_import
  File "<frozen importlib._bootstrap>", line 1027, in _find_and_load
  File "<frozen importlib._bootstrap>", line 1006, in _find_and_load_unlocked
  File "<frozen importlib._bootstrap>", line 688, in _load_unlocked
  File "<frozen importlib._bootstrap_external>", line 883, in exec_module
  File "<frozen importlib._bootstrap>", line 241, in _call_with_frames_removed
  File "/app/SilthsSanctuary/settings/local.py", line 1, in <module>
    from base import *
ModuleNotFoundError: No module named 'base'
[2022-02-04 09:35:18 +0000] [14] [INFO] Worker exiting (pid: 14)
[2022-02-04 09:35:18 +0000] [15] [ERROR] Exception in worker process
Traceback (most recent call last):
  File "/usr/local/lib/python3.10/site-packages/gunicorn/arbiter.py", line 589, in spawn_worker
    worker.init_process()
  File "/usr/local/lib/python3.10/site-packages/gunicorn/workers/base.py", line 134, in init_process
    self.load_wsgi()
  File "/usr/local/lib/python3.10/site-packages/gunicorn/workers/base.py", line 146, in load_wsgi
    self.wsgi = self.app.wsgi()
  File "/usr/local/lib/python3.10/site-packages/gunicorn/app/base.py", line 67, in wsgi
    self.callable = self.load()
  File "/usr/local/lib/python3.10/site-packages/gunicorn/app/wsgiapp.py", line 58, in load
    return self.load_wsgiapp()
  File "/usr/local/lib/python3.10/site-packages/gunicorn/app/wsgiapp.py", line 48, in load_wsgiapp
    return util.import_app(self.app_uri)
  File "/usr/local/lib/python3.10/site-packages/gunicorn/util.py", line 359, in import_app
    mod = importlib.import_module(module)
  File "/usr/local/lib/python3.10/importlib/__init__.py", line 126, in import_module
    return _bootstrap._gcd_import(name[level:], package, level)
  File "<frozen importlib._bootstrap>", line 1050, in _gcd_import
  File "<frozen importlib._bootstrap>", line 1027, in _find_and_load
  File "<frozen importlib._bootstrap>", line 1006, in _find_and_load_unlocked
  File "<frozen importlib._bootstrap>", line 688, in _load_unlocked
  File "<frozen importlib._bootstrap_external>", line 883, in exec_module
  File "<frozen importlib._bootstrap>", line 241, in _call_with_frames_removed
  File "/app/SilthsSanctuary/wsgi.py", line 15, in <module>
    application = get_wsgi_application()
  File "/usr/local/lib/python3.10/site-packages/django/core/wsgi.py", line 12, in get_wsgi_application
    django.setup(set_prefix=False)
  File "/usr/local/lib/python3.10/site-packages/django/__init__.py", line 19, in setup
    configure_logging(settings.LOGGING_CONFIG, settings.LOGGING)
  File "/usr/local/lib/python3.10/site-packages/django/conf/__init__.py", line 84, in __getattr__
    self._setup(name)
  File "/usr/local/lib/python3.10/site-packages/django/conf/__init__.py", line 71, in _setup
    self._wrapped = Settings(settings_module)
  File "/usr/local/lib/python3.10/site-packages/django/conf/__init__.py", line 179, in __init__
    mod = importlib.import_module(self.SETTINGS_MODULE)
  File "/usr/local/lib/python3.10/importlib/__init__.py", line 126, in import_module
    return _bootstrap._gcd_import(name[level:], package, level)
  File "<frozen importlib._bootstrap>", line 1050, in _gcd_import
  File "<frozen importlib._bootstrap>", line 1027, in _find_and_load
  File "<frozen importlib._bootstrap>", line 1006, in _find_and_load_unlocked
  File "<frozen importlib._bootstrap>", line 688, in _load_unlocked
  File "<frozen importlib._bootstrap_external>", line 883, in exec_module
  File "<frozen importlib._bootstrap>", line 241, in _call_with_frames_removed
  File "/app/SilthsSanctuary/settings/local.py", line 1, in <module>
    from base import *
ModuleNotFoundError: No module named 'base'
[2022-02-04 09:35:18 +0000] [15] [INFO] Worker exiting (pid: 15)
[2022-02-04 09:44:51 +0000] [1] [INFO] Starting gunicorn 20.1.0
[2022-02-04 09:44:51 +0000] [1] [INFO] Listening at: http://0.0.0.0:8000 (1)
[2022-02-04 09:44:51 +0000] [1] [INFO] Using worker: sync
[2022-02-04 09:44:51 +0000] [13] [INFO] Booting worker with pid: 13
[2022-02-04 09:44:51 +0000] [14] [INFO] Booting worker with pid: 14
[2022-02-04 09:44:51 +0000] [15] [INFO] Booting worker with pid: 15
[2022-02-04 09:44:51 +0000] [16] [INFO] Booting worker with pid: 16
[2022-02-04 09:44:51 +0000] [13] [ERROR] Exception in worker process
Traceback (most recent call last):
  File "/usr/local/lib/python3.10/site-packages/gunicorn/arbiter.py", line 589, in spawn_worker
    worker.init_process()
  File "/usr/local/lib/python3.10/site-packages/gunicorn/workers/base.py", line 134, in init_process
    self.load_wsgi()
  File "/usr/local/lib/python3.10/site-packages/gunicorn/workers/base.py", line 146, in load_wsgi
    self.wsgi = self.app.wsgi()
  File "/usr/local/lib/python3.10/site-packages/gunicorn/app/base.py", line 67, in wsgi
    self.callable = self.load()
  File "/usr/local/lib/python3.10/site-packages/gunicorn/app/wsgiapp.py", line 58, in load
    return self.load_wsgiapp()
  File "/usr/local/lib/python3.10/site-packages/gunicorn/app/wsgiapp.py", line 48, in load_wsgiapp
    return util.import_app(self.app_uri)
  File "/usr/local/lib/python3.10/site-packages/gunicorn/util.py", line 359, in import_app
    mod = importlib.import_module(module)
  File "/usr/local/lib/python3.10/importlib/__init__.py", line 126, in import_module
    return _bootstrap._gcd_import(name[level:], package, level)
  File "<frozen importlib._bootstrap>", line 1050, in _gcd_import
  File "<frozen importlib._bootstrap>", line 1027, in _find_and_load
  File "<frozen importlib._bootstrap>", line 1006, in _find_and_load_unlocked
  File "<frozen importlib._bootstrap>", line 688, in _load_unlocked
  File "<frozen importlib._bootstrap_external>", line 883, in exec_module
  File "<frozen importlib._bootstrap>", line 241, in _call_with_frames_removed
  File "/app/SilthsSanctuary/wsgi.py", line 15, in <module>
    application = get_wsgi_application()
  File "/usr/local/lib/python3.10/site-packages/django/core/wsgi.py", line 12, in get_wsgi_application
    django.setup(set_prefix=False)
  File "/usr/local/lib/python3.10/site-packages/django/__init__.py", line 19, in setup
    configure_logging(settings.LOGGING_CONFIG, settings.LOGGING)
  File "/usr/local/lib/python3.10/site-packages/django/conf/__init__.py", line 84, in __getattr__
    self._setup(name)
  File "/usr/local/lib/python3.10/site-packages/django/conf/__init__.py", line 71, in _setup
    self._wrapped = Settings(settings_module)
  File "/usr/local/lib/python3.10/site-packages/django/conf/__init__.py", line 179, in __init__
    mod = importlib.import_module(self.SETTINGS_MODULE)
  File "/usr/local/lib/python3.10/importlib/__init__.py", line 126, in import_module
    return _bootstrap._gcd_import(name[level:], package, level)
  File "<frozen importlib._bootstrap>", line 1050, in _gcd_import
  File "<frozen importlib._bootstrap>", line 1027, in _find_and_load
  File "<frozen importlib._bootstrap>", line 1006, in _find_and_load_unlocked
  File "<frozen importlib._bootstrap>", line 688, in _load_unlocked
  File "<frozen importlib._bootstrap_external>", line 883, in exec_module
  File "<frozen importlib._bootstrap>", line 241, in _call_with_frames_removed
  File "/app/SilthsSanctuary/settings/local.py", line 1, in <module>
    from base import *
ModuleNotFoundError: No module named 'base'
[2022-02-04 09:44:51 +0000] [13] [INFO] Worker exiting (pid: 13)
[2022-02-04 09:44:51 +0000] [14] [ERROR] Exception in worker process
Traceback (most recent call last):
  File "/usr/local/lib/python3.10/site-packages/gunicorn/arbiter.py", line 589, in spawn_worker
    worker.init_process()
  File "/usr/local/lib/python3.10/site-packages/gunicorn/workers/base.py", line 134, in init_process
    self.load_wsgi()
  File "/usr/local/lib/python3.10/site-packages/gunicorn/workers/base.py", line 146, in load_wsgi
    self.wsgi = self.app.wsgi()
  File "/usr/local/lib/python3.10/site-packages/gunicorn/app/base.py", line 67, in wsgi
    self.callable = self.load()
  File "/usr/local/lib/python3.10/site-packages/gunicorn/app/wsgiapp.py", line 58, in load
    return self.load_wsgiapp()
  File "/usr/local/lib/python3.10/site-packages/gunicorn/app/wsgiapp.py", line 48, in load_wsgiapp
    return util.import_app(self.app_uri)
  File "/usr/local/lib/python3.10/site-packages/gunicorn/util.py", line 359, in import_app
    mod = importlib.import_module(module)
  File "/usr/local/lib/python3.10/importlib/__init__.py", line 126, in import_module
    return _bootstrap._gcd_import(name[level:], package, level)
  File "<frozen importlib._bootstrap>", line 1050, in _gcd_import
  File "<frozen importlib._bootstrap>", line 1027, in _find_and_load
  File "<frozen importlib._bootstrap>", line 1006, in _find_and_load_unlocked
  File "<frozen importlib._bootstrap>", line 688, in _load_unlocked
  File "<frozen importlib._bootstrap_external>", line 883, in exec_module
  File "<frozen importlib._bootstrap>", line 241, in _call_with_frames_removed
  File "/app/SilthsSanctuary/wsgi.py", line 15, in <module>
    application = get_wsgi_application()
  File "/usr/local/lib/python3.10/site-packages/django/core/wsgi.py", line 12, in get_wsgi_application
    django.setup(set_prefix=False)
  File "/usr/local/lib/python3.10/site-packages/django/__init__.py", line 19, in setup
    configure_logging(settings.LOGGING_CONFIG, settings.LOGGING)
  File "/usr/local/lib/python3.10/site-packages/django/conf/__init__.py", line 84, in __getattr__
    self._setup(name)
  File "/usr/local/lib/python3.10/site-packages/django/conf/__init__.py", line 71, in _setup
    self._wrapped = Settings(settings_module)
  File "/usr/local/lib/python3.10/site-packages/django/conf/__init__.py", line 179, in __init__
    mod = importlib.import_module(self.SETTINGS_MODULE)
  File "/usr/local/lib/python3.10/importlib/__init__.py", line 126, in import_module
    return _bootstrap._gcd_import(name[level:], package, level)
  File "<frozen importlib._bootstrap>", line 1050, in _gcd_import
  File "<frozen importlib._bootstrap>", line 1027, in _find_and_load
  File "<frozen importlib._bootstrap>", line 1006, in _find_and_load_unlocked
  File "<frozen importlib._bootstrap>", line 688, in _load_unlocked
  File "<frozen importlib._bootstrap_external>", line 883, in exec_module
  File "<frozen importlib._bootstrap>", line 241, in _call_with_frames_removed
  File "/app/SilthsSanctuary/settings/local.py", line 1, in <module>
    from base import *
ModuleNotFoundError: No module named 'base'
[2022-02-04 09:44:51 +0000] [14] [INFO] Worker exiting (pid: 14)
[2022-02-04 09:44:51 +0000] [15] [ERROR] Exception in worker process
Traceback (most recent call last):
  File "/usr/local/lib/python3.10/site-packages/gunicorn/arbiter.py", line 589, in spawn_worker
    worker.init_process()
  File "/usr/local/lib/python3.10/site-packages/gunicorn/workers/base.py", line 134, in init_process
    self.load_wsgi()
  File "/usr/local/lib/python3.10/site-packages/gunicorn/workers/base.py", line 146, in load_wsgi
    self.wsgi = self.app.wsgi()
  File "/usr/local/lib/python3.10/site-packages/gunicorn/app/base.py", line 67, in wsgi
    self.callable = self.load()
  File "/usr/local/lib/python3.10/site-packages/gunicorn/app/wsgiapp.py", line 58, in load
    return self.load_wsgiapp()
  File "/usr/local/lib/python3.10/site-packages/gunicorn/app/wsgiapp.py", line 48, in load_wsgiapp
    return util.import_app(self.app_uri)
  File "/usr/local/lib/python3.10/site-packages/gunicorn/util.py", line 359, in import_app
    mod = importlib.import_module(module)
  File "/usr/local/lib/python3.10/importlib/__init__.py", line 126, in import_module
    return _bootstrap._gcd_import(name[level:], package, level)
  File "<frozen importlib._bootstrap>", line 1050, in _gcd_import
  File "<frozen importlib._bootstrap>", line 1027, in _find_and_load
  File "<frozen importlib._bootstrap>", line 1006, in _find_and_load_unlocked
  File "<frozen importlib._bootstrap>", line 688, in _load_unlocked
  File "<frozen importlib._bootstrap_external>", line 883, in exec_module
  File "<frozen importlib._bootstrap>", line 241, in _call_with_frames_removed
  File "/app/SilthsSanctuary/wsgi.py", line 15, in <module>
    application = get_wsgi_application()
  File "/usr/local/lib/python3.10/site-packages/django/core/wsgi.py", line 12, in get_wsgi_application
    django.setup(set_prefix=False)
  File "/usr/local/lib/python3.10/site-packages/django/__init__.py", line 19, in setup
    configure_logging(settings.LOGGING_CONFIG, settings.LOGGING)
  File "/usr/local/lib/python3.10/site-packages/django/conf/__init__.py", line 84, in __getattr__
    self._setup(name)
  File "/usr/local/lib/python3.10/site-packages/django/conf/__init__.py", line 71, in _setup
    self._wrapped = Settings(settings_module)
  File "/usr/local/lib/python3.10/site-packages/django/conf/__init__.py", line 179, in __init__
    mod = importlib.import_module(self.SETTINGS_MODULE)
  File "/usr/local/lib/python3.10/importlib/__init__.py", line 126, in import_module
    return _bootstrap._gcd_import(name[level:], package, level)
  File "<frozen importlib._bootstrap>", line 1050, in _gcd_import
  File "<frozen importlib._bootstrap>", line 1027, in _find_and_load
  File "<frozen importlib._bootstrap>", line 1006, in _find_and_load_unlocked
  File "<frozen importlib._bootstrap>", line 688, in _load_unlocked
  File "<frozen importlib._bootstrap_external>", line 883, in exec_module
  File "<frozen importlib._bootstrap>", line 241, in _call_with_frames_removed
  File "/app/SilthsSanctuary/settings/local.py", line 1, in <module>
    from base import *
ModuleNotFoundError: No module named 'base'
[2022-02-04 09:44:51 +0000] [15] [INFO] Worker exiting (pid: 15)
[2022-02-04 09:44:52 +0000] [16] [ERROR] Exception in worker process
Traceback (most recent call last):
  File "/usr/local/lib/python3.10/site-packages/gunicorn/arbiter.py", line 589, in spawn_worker
    worker.init_process()
  File "/usr/local/lib/python3.10/site-packages/gunicorn/workers/base.py", line 134, in init_process
    self.load_wsgi()
  File "/usr/local/lib/python3.10/site-packages/gunicorn/workers/base.py", line 146, in load_wsgi
    self.wsgi = self.app.wsgi()
  File "/usr/local/lib/python3.10/site-packages/gunicorn/app/base.py", line 67, in wsgi
    self.callable = self.load()
  File "/usr/local/lib/python3.10/site-packages/gunicorn/app/wsgiapp.py", line 58, in load
    return self.load_wsgiapp()
  File "/usr/local/lib/python3.10/site-packages/gunicorn/app/wsgiapp.py", line 48, in load_wsgiapp
    return util.import_app(self.app_uri)
  File "/usr/local/lib/python3.10/site-packages/gunicorn/util.py", line 359, in import_app
    mod = importlib.import_module(module)
  File "/usr/local/lib/python3.10/importlib/__init__.py", line 126, in import_module
    return _bootstrap._gcd_import(name[level:], package, level)
  File "<frozen importlib._bootstrap>", line 1050, in _gcd_import
  File "<frozen importlib._bootstrap>", line 1027, in _find_and_load
  File "<frozen importlib._bootstrap>", line 1006, in _find_and_load_unlocked
  File "<frozen importlib._bootstrap>", line 688, in _load_unlocked
  File "<frozen importlib._bootstrap_external>", line 883, in exec_module
  File "<frozen importlib._bootstrap>", line 241, in _call_with_frames_removed
  File "/app/SilthsSanctuary/wsgi.py", line 15, in <module>
    application = get_wsgi_application()
  File "/usr/local/lib/python3.10/site-packages/django/core/wsgi.py", line 12, in get_wsgi_application
    django.setup(set_prefix=False)
  File "/usr/local/lib/python3.10/site-packages/django/__init__.py", line 19, in setup
    configure_logging(settings.LOGGING_CONFIG, settings.LOGGING)
  File "/usr/local/lib/python3.10/site-packages/django/conf/__init__.py", line 84, in __getattr__
    self._setup(name)
  File "/usr/local/lib/python3.10/site-packages/django/conf/__init__.py", line 71, in _setup
    self._wrapped = Settings(settings_module)
  File "/usr/local/lib/python3.10/site-packages/django/conf/__init__.py", line 179, in __init__
    mod = importlib.import_module(self.SETTINGS_MODULE)
  File "/usr/local/lib/python3.10/importlib/__init__.py", line 126, in import_module
    return _bootstrap._gcd_import(name[level:], package, level)
  File "<frozen importlib._bootstrap>", line 1050, in _gcd_import
  File "<frozen importlib._bootstrap>", line 1027, in _find_and_load
  File "<frozen importlib._bootstrap>", line 1006, in _find_and_load_unlocked
  File "<frozen importlib._bootstrap>", line 688, in _load_unlocked
  File "<frozen importlib._bootstrap_external>", line 883, in exec_module
  File "<frozen importlib._bootstrap>", line 241, in _call_with_frames_removed
  File "/app/SilthsSanctuary/settings/local.py", line 1, in <module>
    from base import *
ModuleNotFoundError: No module named 'base'
[2022-02-04 09:44:52 +0000] [16] [INFO] Worker exiting (pid: 16)
[2022-02-04 09:50:11 +0000] [1] [INFO] Starting gunicorn 20.1.0
[2022-02-04 09:50:11 +0000] [1] [INFO] Listening at: http://0.0.0.0:8000 (1)
[2022-02-04 09:50:11 +0000] [1] [INFO] Using worker: sync
[2022-02-04 09:50:11 +0000] [13] [INFO] Booting worker with pid: 13
[2022-02-04 09:50:11 +0000] [14] [INFO] Booting worker with pid: 14
[2022-02-04 09:50:11 +0000] [15] [INFO] Booting worker with pid: 15
[2022-02-04 09:50:11 +0000] [16] [INFO] Booting worker with pid: 16
[2022-02-04 09:50:11 +0000] [13] [ERROR] Exception in worker process
Traceback (most recent call last):
  File "/usr/local/lib/python3.10/site-packages/gunicorn/arbiter.py", line 589, in spawn_worker
    worker.init_process()
  File "/usr/local/lib/python3.10/site-packages/gunicorn/workers/base.py", line 134, in init_process
    self.load_wsgi()
  File "/usr/local/lib/python3.10/site-packages/gunicorn/workers/base.py", line 146, in load_wsgi
    self.wsgi = self.app.wsgi()
  File "/usr/local/lib/python3.10/site-packages/gunicorn/app/base.py", line 67, in wsgi
    self.callable = self.load()
  File "/usr/local/lib/python3.10/site-packages/gunicorn/app/wsgiapp.py", line 58, in load
    return self.load_wsgiapp()
  File "/usr/local/lib/python3.10/site-packages/gunicorn/app/wsgiapp.py", line 48, in load_wsgiapp
    return util.import_app(self.app_uri)
  File "/usr/local/lib/python3.10/site-packages/gunicorn/util.py", line 359, in import_app
    mod = importlib.import_module(module)
  File "/usr/local/lib/python3.10/importlib/__init__.py", line 126, in import_module
    return _bootstrap._gcd_import(name[level:], package, level)
  File "<frozen importlib._bootstrap>", line 1050, in _gcd_import
  File "<frozen importlib._bootstrap>", line 1027, in _find_and_load
  File "<frozen importlib._bootstrap>", line 1006, in _find_and_load_unlocked
  File "<frozen importlib._bootstrap>", line 688, in _load_unlocked
  File "<frozen importlib._bootstrap_external>", line 883, in exec_module
  File "<frozen importlib._bootstrap>", line 241, in _call_with_frames_removed
  File "/app/SilthsSanctuary/wsgi.py", line 15, in <module>
    application = get_wsgi_application()
  File "/usr/local/lib/python3.10/site-packages/django/core/wsgi.py", line 12, in get_wsgi_application
    django.setup(set_prefix=False)
  File "/usr/local/lib/python3.10/site-packages/django/__init__.py", line 19, in setup
    configure_logging(settings.LOGGING_CONFIG, settings.LOGGING)
  File "/usr/local/lib/python3.10/site-packages/django/conf/__init__.py", line 84, in __getattr__
    self._setup(name)
  File "/usr/local/lib/python3.10/site-packages/django/conf/__init__.py", line 71, in _setup
    self._wrapped = Settings(settings_module)
  File "/usr/local/lib/python3.10/site-packages/django/conf/__init__.py", line 179, in __init__
    mod = importlib.import_module(self.SETTINGS_MODULE)
  File "/usr/local/lib/python3.10/importlib/__init__.py", line 126, in import_module
    return _bootstrap._gcd_import(name[level:], package, level)
  File "<frozen importlib._bootstrap>", line 1050, in _gcd_import
  File "<frozen importlib._bootstrap>", line 1027, in _find_and_load
  File "<frozen importlib._bootstrap>", line 1006, in _find_and_load_unlocked
  File "<frozen importlib._bootstrap>", line 688, in _load_unlocked
  File "<frozen importlib._bootstrap_external>", line 883, in exec_module
  File "<frozen importlib._bootstrap>", line 241, in _call_with_frames_removed
  File "/app/SilthsSanctuary/settings/local.py", line 1, in <module>
    from base import *
ModuleNotFoundError: No module named 'base'
[2022-02-04 09:50:11 +0000] [13] [INFO] Worker exiting (pid: 13)
[2022-02-04 09:50:11 +0000] [14] [ERROR] Exception in worker process
Traceback (most recent call last):
  File "/usr/local/lib/python3.10/site-packages/gunicorn/arbiter.py", line 589, in spawn_worker
    worker.init_process()
  File "/usr/local/lib/python3.10/site-packages/gunicorn/workers/base.py", line 134, in init_process
    self.load_wsgi()
  File "/usr/local/lib/python3.10/site-packages/gunicorn/workers/base.py", line 146, in load_wsgi
    self.wsgi = self.app.wsgi()
  File "/usr/local/lib/python3.10/site-packages/gunicorn/app/base.py", line 67, in wsgi
    self.callable = self.load()
  File "/usr/local/lib/python3.10/site-packages/gunicorn/app/wsgiapp.py", line 58, in load
    return self.load_wsgiapp()
  File "/usr/local/lib/python3.10/site-packages/gunicorn/app/wsgiapp.py", line 48, in load_wsgiapp
    return util.import_app(self.app_uri)
  File "/usr/local/lib/python3.10/site-packages/gunicorn/util.py", line 359, in import_app
    mod = importlib.import_module(module)
  File "/usr/local/lib/python3.10/importlib/__init__.py", line 126, in import_module
    return _bootstrap._gcd_import(name[level:], package, level)
  File "<frozen importlib._bootstrap>", line 1050, in _gcd_import
  File "<frozen importlib._bootstrap>", line 1027, in _find_and_load
  File "<frozen importlib._bootstrap>", line 1006, in _find_and_load_unlocked
  File "<frozen importlib._bootstrap>", line 688, in _load_unlocked
  File "<frozen importlib._bootstrap_external>", line 883, in exec_module
  File "<frozen importlib._bootstrap>", line 241, in _call_with_frames_removed
  File "/app/SilthsSanctuary/wsgi.py", line 15, in <module>
    application = get_wsgi_application()
  File "/usr/local/lib/python3.10/site-packages/django/core/wsgi.py", line 12, in get_wsgi_application
    django.setup(set_prefix=False)
  File "/usr/local/lib/python3.10/site-packages/django/__init__.py", line 19, in setup
    configure_logging(settings.LOGGING_CONFIG, settings.LOGGING)
  File "/usr/local/lib/python3.10/site-packages/django/conf/__init__.py", line 84, in __getattr__
    self._setup(name)
  File "/usr/local/lib/python3.10/site-packages/django/conf/__init__.py", line 71, in _setup
    self._wrapped = Settings(settings_module)
  File "/usr/local/lib/python3.10/site-packages/django/conf/__init__.py", line 179, in __init__
    mod = importlib.import_module(self.SETTINGS_MODULE)
  File "/usr/local/lib/python3.10/importlib/__init__.py", line 126, in import_module
    return _bootstrap._gcd_import(name[level:], package, level)
  File "<frozen importlib._bootstrap>", line 1050, in _gcd_import
  File "<frozen importlib._bootstrap>", line 1027, in _find_and_load
  File "<frozen importlib._bootstrap>", line 1006, in _find_and_load_unlocked
  File "<frozen importlib._bootstrap>", line 688, in _load_unlocked
  File "<frozen importlib._bootstrap_external>", line 883, in exec_module
  File "<frozen importlib._bootstrap>", line 241, in _call_with_frames_removed
  File "/app/SilthsSanctuary/settings/local.py", line 1, in <module>
    from base import *
ModuleNotFoundError: No module named 'base'
[2022-02-04 09:50:11 +0000] [14] [INFO] Worker exiting (pid: 14)
[2022-02-04 09:50:11 +0000] [15] [ERROR] Exception in worker process
Traceback (most recent call last):
  File "/usr/local/lib/python3.10/site-packages/gunicorn/arbiter.py", line 589, in spawn_worker
    worker.init_process()
  File "/usr/local/lib/python3.10/site-packages/gunicorn/workers/base.py", line 134, in init_process
    self.load_wsgi()
  File "/usr/local/lib/python3.10/site-packages/gunicorn/workers/base.py", line 146, in load_wsgi
    self.wsgi = self.app.wsgi()
  File "/usr/local/lib/python3.10/site-packages/gunicorn/app/base.py", line 67, in wsgi
    self.callable = self.load()
  File "/usr/local/lib/python3.10/site-packages/gunicorn/app/wsgiapp.py", line 58, in load
    return self.load_wsgiapp()
  File "/usr/local/lib/python3.10/site-packages/gunicorn/app/wsgiapp.py", line 48, in load_wsgiapp
    return util.import_app(self.app_uri)
  File "/usr/local/lib/python3.10/site-packages/gunicorn/util.py", line 359, in import_app
    mod = importlib.import_module(module)
  File "/usr/local/lib/python3.10/importlib/__init__.py", line 126, in import_module
    return _bootstrap._gcd_import(name[level:], package, level)
  File "<frozen importlib._bootstrap>", line 1050, in _gcd_import
  File "<frozen importlib._bootstrap>", line 1027, in _find_and_load
  File "<frozen importlib._bootstrap>", line 1006, in _find_and_load_unlocked
  File "<frozen importlib._bootstrap>", line 688, in _load_unlocked
  File "<frozen importlib._bootstrap_external>", line 883, in exec_module
  File "<frozen importlib._bootstrap>", line 241, in _call_with_frames_removed
  File "/app/SilthsSanctuary/wsgi.py", line 15, in <module>
    application = get_wsgi_application()
  File "/usr/local/lib/python3.10/site-packages/django/core/wsgi.py", line 12, in get_wsgi_application
    django.setup(set_prefix=False)
  File "/usr/local/lib/python3.10/site-packages/django/__init__.py", line 19, in setup
    configure_logging(settings.LOGGING_CONFIG, settings.LOGGING)
  File "/usr/local/lib/python3.10/site-packages/django/conf/__init__.py", line 84, in __getattr__
    self._setup(name)
  File "/usr/local/lib/python3.10/site-packages/django/conf/__init__.py", line 71, in _setup
    self._wrapped = Settings(settings_module)
  File "/usr/local/lib/python3.10/site-packages/django/conf/__init__.py", line 179, in __init__
    mod = importlib.import_module(self.SETTINGS_MODULE)
  File "/usr/local/lib/python3.10/importlib/__init__.py", line 126, in import_module
    return _bootstrap._gcd_import(name[level:], package, level)
  File "<frozen importlib._bootstrap>", line 1050, in _gcd_import
  File "<frozen importlib._bootstrap>", line 1027, in _find_and_load
  File "<frozen importlib._bootstrap>", line 1006, in _find_and_load_unlocked
  File "<frozen importlib._bootstrap>", line 688, in _load_unlocked
  File "<frozen importlib._bootstrap_external>", line 883, in exec_module
  File "<frozen importlib._bootstrap>", line 241, in _call_with_frames_removed
  File "/app/SilthsSanctuary/settings/local.py", line 1, in <module>
    from base import *
ModuleNotFoundError: No module named 'base'
[2022-02-04 09:50:11 +0000] [15] [INFO] Worker exiting (pid: 15)
[2022-02-04 10:04:30 +0000] [1] [INFO] Starting gunicorn 20.1.0
[2022-02-04 10:04:30 +0000] [1] [INFO] Listening at: http://0.0.0.0:8000 (1)
[2022-02-04 10:04:30 +0000] [1] [INFO] Using worker: sync
[2022-02-04 10:04:30 +0000] [13] [INFO] Booting worker with pid: 13
[2022-02-04 10:04:30 +0000] [14] [INFO] Booting worker with pid: 14
[2022-02-04 10:04:30 +0000] [15] [INFO] Booting worker with pid: 15
[2022-02-04 10:04:30 +0000] [16] [INFO] Booting worker with pid: 16
[2022-02-04 10:04:30 +0000] [13] [ERROR] Exception in worker process
Traceback (most recent call last):
  File "/usr/local/lib/python3.10/site-packages/gunicorn/arbiter.py", line 589, in spawn_worker
    worker.init_process()
  File "/usr/local/lib/python3.10/site-packages/gunicorn/workers/base.py", line 134, in init_process
    self.load_wsgi()
  File "/usr/local/lib/python3.10/site-packages/gunicorn/workers/base.py", line 146, in load_wsgi
    self.wsgi = self.app.wsgi()
  File "/usr/local/lib/python3.10/site-packages/gunicorn/app/base.py", line 67, in wsgi
    self.callable = self.load()
  File "/usr/local/lib/python3.10/site-packages/gunicorn/app/wsgiapp.py", line 58, in load
    return self.load_wsgiapp()
  File "/usr/local/lib/python3.10/site-packages/gunicorn/app/wsgiapp.py", line 48, in load_wsgiapp
    return util.import_app(self.app_uri)
  File "/usr/local/lib/python3.10/site-packages/gunicorn/util.py", line 359, in import_app
    mod = importlib.import_module(module)
  File "/usr/local/lib/python3.10/importlib/__init__.py", line 126, in import_module
    return _bootstrap._gcd_import(name[level:], package, level)
  File "<frozen importlib._bootstrap>", line 1050, in _gcd_import
  File "<frozen importlib._bootstrap>", line 1027, in _find_and_load
  File "<frozen importlib._bootstrap>", line 1006, in _find_and_load_unlocked
  File "<frozen importlib._bootstrap>", line 688, in _load_unlocked
  File "<frozen importlib._bootstrap_external>", line 883, in exec_module
  File "<frozen importlib._bootstrap>", line 241, in _call_with_frames_removed
  File "/app/SilthsSanctuary/wsgi.py", line 15, in <module>
    application = get_wsgi_application()
  File "/usr/local/lib/python3.10/site-packages/django/core/wsgi.py", line 12, in get_wsgi_application
    django.setup(set_prefix=False)
  File "/usr/local/lib/python3.10/site-packages/django/__init__.py", line 19, in setup
    configure_logging(settings.LOGGING_CONFIG, settings.LOGGING)
  File "/usr/local/lib/python3.10/site-packages/django/conf/__init__.py", line 84, in __getattr__
    self._setup(name)
  File "/usr/local/lib/python3.10/site-packages/django/conf/__init__.py", line 71, in _setup
    self._wrapped = Settings(settings_module)
  File "/usr/local/lib/python3.10/site-packages/django/conf/__init__.py", line 179, in __init__
    mod = importlib.import_module(self.SETTINGS_MODULE)
  File "/usr/local/lib/python3.10/importlib/__init__.py", line 126, in import_module
    return _bootstrap._gcd_import(name[level:], package, level)
  File "<frozen importlib._bootstrap>", line 1050, in _gcd_import
  File "<frozen importlib._bootstrap>", line 1027, in _find_and_load
  File "<frozen importlib._bootstrap>", line 1006, in _find_and_load_unlocked
  File "<frozen importlib._bootstrap>", line 688, in _load_unlocked
  File "<frozen importlib._bootstrap_external>", line 883, in exec_module
  File "<frozen importlib._bootstrap>", line 241, in _call_with_frames_removed
  File "/app/SilthsSanctuary/settings/local.py", line 1, in <module>
    from base import *
ModuleNotFoundError: No module named 'base'
[2022-02-04 10:04:30 +0000] [13] [INFO] Worker exiting (pid: 13)
[2022-02-04 10:04:30 +0000] [14] [ERROR] Exception in worker process
Traceback (most recent call last):
  File "/usr/local/lib/python3.10/site-packages/gunicorn/arbiter.py", line 589, in spawn_worker
    worker.init_process()
  File "/usr/local/lib/python3.10/site-packages/gunicorn/workers/base.py", line 134, in init_process
    self.load_wsgi()
  File "/usr/local/lib/python3.10/site-packages/gunicorn/workers/base.py", line 146, in load_wsgi
    self.wsgi = self.app.wsgi()
  File "/usr/local/lib/python3.10/site-packages/gunicorn/app/base.py", line 67, in wsgi
    self.callable = self.load()
  File "/usr/local/lib/python3.10/site-packages/gunicorn/app/wsgiapp.py", line 58, in load
    return self.load_wsgiapp()
  File "/usr/local/lib/python3.10/site-packages/gunicorn/app/wsgiapp.py", line 48, in load_wsgiapp
    return util.import_app(self.app_uri)
  File "/usr/local/lib/python3.10/site-packages/gunicorn/util.py", line 359, in import_app
    mod = importlib.import_module(module)
  File "/usr/local/lib/python3.10/importlib/__init__.py", line 126, in import_module
    return _bootstrap._gcd_import(name[level:], package, level)
  File "<frozen importlib._bootstrap>", line 1050, in _gcd_import
  File "<frozen importlib._bootstrap>", line 1027, in _find_and_load
  File "<frozen importlib._bootstrap>", line 1006, in _find_and_load_unlocked
  File "<frozen importlib._bootstrap>", line 688, in _load_unlocked
  File "<frozen importlib._bootstrap_external>", line 883, in exec_module
  File "<frozen importlib._bootstrap>", line 241, in _call_with_frames_removed
  File "/app/SilthsSanctuary/wsgi.py", line 15, in <module>
    application = get_wsgi_application()
  File "/usr/local/lib/python3.10/site-packages/django/core/wsgi.py", line 12, in get_wsgi_application
    django.setup(set_prefix=False)
  File "/usr/local/lib/python3.10/site-packages/django/__init__.py", line 19, in setup
    configure_logging(settings.LOGGING_CONFIG, settings.LOGGING)
  File "/usr/local/lib/python3.10/site-packages/django/conf/__init__.py", line 84, in __getattr__
    self._setup(name)
  File "/usr/local/lib/python3.10/site-packages/django/conf/__init__.py", line 71, in _setup
    self._wrapped = Settings(settings_module)
  File "/usr/local/lib/python3.10/site-packages/django/conf/__init__.py", line 179, in __init__
    mod = importlib.import_module(self.SETTINGS_MODULE)
  File "/usr/local/lib/python3.10/importlib/__init__.py", line 126, in import_module
    return _bootstrap._gcd_import(name[level:], package, level)
  File "<frozen importlib._bootstrap>", line 1050, in _gcd_import
  File "<frozen importlib._bootstrap>", line 1027, in _find_and_load
  File "<frozen importlib._bootstrap>", line 1006, in _find_and_load_unlocked
  File "<frozen importlib._bootstrap>", line 688, in _load_unlocked
  File "<frozen importlib._bootstrap_external>", line 883, in exec_module
  File "<frozen importlib._bootstrap>", line 241, in _call_with_frames_removed
  File "/app/SilthsSanctuary/settings/local.py", line 1, in <module>
    from base import *
ModuleNotFoundError: No module named 'base'
[2022-02-04 10:04:30 +0000] [14] [INFO] Worker exiting (pid: 14)
[2022-02-04 10:04:30 +0000] [15] [ERROR] Exception in worker process
Traceback (most recent call last):
  File "/usr/local/lib/python3.10/site-packages/gunicorn/arbiter.py", line 589, in spawn_worker
    worker.init_process()
  File "/usr/local/lib/python3.10/site-packages/gunicorn/workers/base.py", line 134, in init_process
    self.load_wsgi()
  File "/usr/local/lib/python3.10/site-packages/gunicorn/workers/base.py", line 146, in load_wsgi
    self.wsgi = self.app.wsgi()
  File "/usr/local/lib/python3.10/site-packages/gunicorn/app/base.py", line 67, in wsgi
    self.callable = self.load()
  File "/usr/local/lib/python3.10/site-packages/gunicorn/app/wsgiapp.py", line 58, in load
    return self.load_wsgiapp()
  File "/usr/local/lib/python3.10/site-packages/gunicorn/app/wsgiapp.py", line 48, in load_wsgiapp
    return util.import_app(self.app_uri)
  File "/usr/local/lib/python3.10/site-packages/gunicorn/util.py", line 359, in import_app
    mod = importlib.import_module(module)
  File "/usr/local/lib/python3.10/importlib/__init__.py", line 126, in import_module
    return _bootstrap._gcd_import(name[level:], package, level)
  File "<frozen importlib._bootstrap>", line 1050, in _gcd_import
  File "<frozen importlib._bootstrap>", line 1027, in _find_and_load
  File "<frozen importlib._bootstrap>", line 1006, in _find_and_load_unlocked
  File "<frozen importlib._bootstrap>", line 688, in _load_unlocked
  File "<frozen importlib._bootstrap_external>", line 883, in exec_module
  File "<frozen importlib._bootstrap>", line 241, in _call_with_frames_removed
  File "/app/SilthsSanctuary/wsgi.py", line 15, in <module>
    application = get_wsgi_application()
  File "/usr/local/lib/python3.10/site-packages/django/core/wsgi.py", line 12, in get_wsgi_application
    django.setup(set_prefix=False)
  File "/usr/local/lib/python3.10/site-packages/django/__init__.py", line 19, in setup
    configure_logging(settings.LOGGING_CONFIG, settings.LOGGING)
  File "/usr/local/lib/python3.10/site-packages/django/conf/__init__.py", line 84, in __getattr__
    self._setup(name)
  File "/usr/local/lib/python3.10/site-packages/django/conf/__init__.py", line 71, in _setup
    self._wrapped = Settings(settings_module)
  File "/usr/local/lib/python3.10/site-packages/django/conf/__init__.py", line 179, in __init__
    mod = importlib.import_module(self.SETTINGS_MODULE)
  File "/usr/local/lib/python3.10/importlib/__init__.py", line 126, in import_module
    return _bootstrap._gcd_import(name[level:], package, level)
  File "<frozen importlib._bootstrap>", line 1050, in _gcd_import
  File "<frozen importlib._bootstrap>", line 1027, in _find_and_load
  File "<frozen importlib._bootstrap>", line 1006, in _find_and_load_unlocked
  File "<frozen importlib._bootstrap>", line 688, in _load_unlocked
  File "<frozen importlib._bootstrap_external>", line 883, in exec_module
  File "<frozen importlib._bootstrap>", line 241, in _call_with_frames_removed
  File "/app/SilthsSanctuary/settings/local.py", line 1, in <module>
    from base import *
ModuleNotFoundError: No module named 'base'
[2022-02-04 10:04:30 +0000] [15] [INFO] Worker exiting (pid: 15)
[2022-02-04 10:04:30 +0000] [1] [WARNING] Worker with pid 15 was terminated due to signal 15
[2022-02-04 10:04:30 +0000] [1] [WARNING] Worker with pid 14 was terminated due to signal 15
[2022-02-04 10:04:30 +0000] [16] [ERROR] Exception in worker process
Traceback (most recent call last):
  File "/usr/local/lib/python3.10/site-packages/gunicorn/arbiter.py", line 589, in spawn_worker
    worker.init_process()
  File "/usr/local/lib/python3.10/site-packages/gunicorn/workers/base.py", line 134, in init_process
    self.load_wsgi()
  File "/usr/local/lib/python3.10/site-packages/gunicorn/workers/base.py", line 146, in load_wsgi
    self.wsgi = self.app.wsgi()
  File "/usr/local/lib/python3.10/site-packages/gunicorn/app/base.py", line 67, in wsgi
    self.callable = self.load()
  File "/usr/local/lib/python3.10/site-packages/gunicorn/app/wsgiapp.py", line 58, in load
    return self.load_wsgiapp()
  File "/usr/local/lib/python3.10/site-packages/gunicorn/app/wsgiapp.py", line 48, in load_wsgiapp
    return util.import_app(self.app_uri)
  File "/usr/local/lib/python3.10/site-packages/gunicorn/util.py", line 359, in import_app
    mod = importlib.import_module(module)
  File "/usr/local/lib/python3.10/importlib/__init__.py", line 126, in import_module
    return _bootstrap._gcd_import(name[level:], package, level)
  File "<frozen importlib._bootstrap>", line 1050, in _gcd_import
  File "<frozen importlib._bootstrap>", line 1027, in _find_and_load
  File "<frozen importlib._bootstrap>", line 1006, in _find_and_load_unlocked
  File "<frozen importlib._bootstrap>", line 688, in _load_unlocked
  File "<frozen importlib._bootstrap_external>", line 883, in exec_module
  File "<frozen importlib._bootstrap>", line 241, in _call_with_frames_removed
  File "/app/SilthsSanctuary/wsgi.py", line 15, in <module>
    application = get_wsgi_application()
  File "/usr/local/lib/python3.10/site-packages/django/core/wsgi.py", line 12, in get_wsgi_application
    django.setup(set_prefix=False)
  File "/usr/local/lib/python3.10/site-packages/django/__init__.py", line 19, in setup
    configure_logging(settings.LOGGING_CONFIG, settings.LOGGING)
  File "/usr/local/lib/python3.10/site-packages/django/conf/__init__.py", line 84, in __getattr__
    self._setup(name)
  File "/usr/local/lib/python3.10/site-packages/django/conf/__init__.py", line 71, in _setup
    self._wrapped = Settings(settings_module)
  File "/usr/local/lib/python3.10/site-packages/django/conf/__init__.py", line 179, in __init__
    mod = importlib.import_module(self.SETTINGS_MODULE)
  File "/usr/local/lib/python3.10/importlib/__init__.py", line 126, in import_module
    return _bootstrap._gcd_import(name[level:], package, level)
  File "<frozen importlib._bootstrap>", line 1050, in _gcd_import
  File "<frozen importlib._bootstrap>", line 1027, in _find_and_load
  File "<frozen importlib._bootstrap>", line 1006, in _find_and_load_unlocked
  File "<frozen importlib._bootstrap>", line 688, in _load_unlocked
  File "<frozen importlib._bootstrap_external>", line 883, in exec_module
  File "<frozen importlib._bootstrap>", line 241, in _call_with_frames_removed
  File "/app/SilthsSanctuary/settings/local.py", line 1, in <module>
    from base import *
ModuleNotFoundError: No module named 'base'
[2022-02-04 10:04:30 +0000] [16] [INFO] Worker exiting (pid: 16)
[2022-02-04 10:05:10 +0000] [1] [INFO] Starting gunicorn 20.1.0
[2022-02-04 10:05:10 +0000] [1] [INFO] Listening at: http://0.0.0.0:8000 (1)
[2022-02-04 10:05:10 +0000] [1] [INFO] Using worker: sync
[2022-02-04 10:05:10 +0000] [12] [INFO] Booting worker with pid: 12
[2022-02-04 10:05:10 +0000] [13] [INFO] Booting worker with pid: 13
[2022-02-04 10:05:10 +0000] [14] [INFO] Booting worker with pid: 14
[2022-02-04 10:05:10 +0000] [15] [INFO] Booting worker with pid: 15
[2022-02-04 10:05:11 +0000] [12] [ERROR] Exception in worker process
Traceback (most recent call last):
  File "/usr/local/lib/python3.10/site-packages/gunicorn/arbiter.py", line 589, in spawn_worker
    worker.init_process()
  File "/usr/local/lib/python3.10/site-packages/gunicorn/workers/base.py", line 134, in init_process
    self.load_wsgi()
  File "/usr/local/lib/python3.10/site-packages/gunicorn/workers/base.py", line 146, in load_wsgi
    self.wsgi = self.app.wsgi()
  File "/usr/local/lib/python3.10/site-packages/gunicorn/app/base.py", line 67, in wsgi
    self.callable = self.load()
  File "/usr/local/lib/python3.10/site-packages/gunicorn/app/wsgiapp.py", line 58, in load
    return self.load_wsgiapp()
  File "/usr/local/lib/python3.10/site-packages/gunicorn/app/wsgiapp.py", line 48, in load_wsgiapp
    return util.import_app(self.app_uri)
  File "/usr/local/lib/python3.10/site-packages/gunicorn/util.py", line 359, in import_app
    mod = importlib.import_module(module)
  File "/usr/local/lib/python3.10/importlib/__init__.py", line 126, in import_module
    return _bootstrap._gcd_import(name[level:], package, level)
  File "<frozen importlib._bootstrap>", line 1050, in _gcd_import
  File "<frozen importlib._bootstrap>", line 1027, in _find_and_load
  File "<frozen importlib._bootstrap>", line 1006, in _find_and_load_unlocked
  File "<frozen importlib._bootstrap>", line 688, in _load_unlocked
  File "<frozen importlib._bootstrap_external>", line 883, in exec_module
  File "<frozen importlib._bootstrap>", line 241, in _call_with_frames_removed
  File "/app/SilthsSanctuary/wsgi.py", line 15, in <module>
    application = get_wsgi_application()
  File "/usr/local/lib/python3.10/site-packages/django/core/wsgi.py", line 12, in get_wsgi_application
    django.setup(set_prefix=False)
  File "/usr/local/lib/python3.10/site-packages/django/__init__.py", line 19, in setup
    configure_logging(settings.LOGGING_CONFIG, settings.LOGGING)
  File "/usr/local/lib/python3.10/site-packages/django/conf/__init__.py", line 84, in __getattr__
    self._setup(name)
  File "/usr/local/lib/python3.10/site-packages/django/conf/__init__.py", line 71, in _setup
    self._wrapped = Settings(settings_module)
  File "/usr/local/lib/python3.10/site-packages/django/conf/__init__.py", line 179, in __init__
    mod = importlib.import_module(self.SETTINGS_MODULE)
  File "/usr/local/lib/python3.10/importlib/__init__.py", line 126, in import_module
    return _bootstrap._gcd_import(name[level:], package, level)
  File "<frozen importlib._bootstrap>", line 1050, in _gcd_import
  File "<frozen importlib._bootstrap>", line 1027, in _find_and_load
  File "<frozen importlib._bootstrap>", line 1006, in _find_and_load_unlocked
  File "<frozen importlib._bootstrap>", line 688, in _load_unlocked
  File "<frozen importlib._bootstrap_external>", line 883, in exec_module
  File "<frozen importlib._bootstrap>", line 241, in _call_with_frames_removed
  File "/app/SilthsSanctuary/settings/local.py", line 1, in <module>
    from base import *
ModuleNotFoundError: No module named 'base'
[2022-02-04 10:05:11 +0000] [12] [INFO] Worker exiting (pid: 12)
[2022-02-04 10:05:11 +0000] [13] [ERROR] Exception in worker process
Traceback (most recent call last):
  File "/usr/local/lib/python3.10/site-packages/gunicorn/arbiter.py", line 589, in spawn_worker
    worker.init_process()
  File "/usr/local/lib/python3.10/site-packages/gunicorn/workers/base.py", line 134, in init_process
    self.load_wsgi()
  File "/usr/local/lib/python3.10/site-packages/gunicorn/workers/base.py", line 146, in load_wsgi
    self.wsgi = self.app.wsgi()
  File "/usr/local/lib/python3.10/site-packages/gunicorn/app/base.py", line 67, in wsgi
    self.callable = self.load()
  File "/usr/local/lib/python3.10/site-packages/gunicorn/app/wsgiapp.py", line 58, in load
    return self.load_wsgiapp()
  File "/usr/local/lib/python3.10/site-packages/gunicorn/app/wsgiapp.py", line 48, in load_wsgiapp
    return util.import_app(self.app_uri)
  File "/usr/local/lib/python3.10/site-packages/gunicorn/util.py", line 359, in import_app
    mod = importlib.import_module(module)
  File "/usr/local/lib/python3.10/importlib/__init__.py", line 126, in import_module
    return _bootstrap._gcd_import(name[level:], package, level)
  File "<frozen importlib._bootstrap>", line 1050, in _gcd_import
  File "<frozen importlib._bootstrap>", line 1027, in _find_and_load
  File "<frozen importlib._bootstrap>", line 1006, in _find_and_load_unlocked
  File "<frozen importlib._bootstrap>", line 688, in _load_unlocked
  File "<frozen importlib._bootstrap_external>", line 883, in exec_module
  File "<frozen importlib._bootstrap>", line 241, in _call_with_frames_removed
  File "/app/SilthsSanctuary/wsgi.py", line 15, in <module>
    application = get_wsgi_application()
  File "/usr/local/lib/python3.10/site-packages/django/core/wsgi.py", line 12, in get_wsgi_application
    django.setup(set_prefix=False)
  File "/usr/local/lib/python3.10/site-packages/django/__init__.py", line 19, in setup
    configure_logging(settings.LOGGING_CONFIG, settings.LOGGING)
  File "/usr/local/lib/python3.10/site-packages/django/conf/__init__.py", line 84, in __getattr__
    self._setup(name)
  File "/usr/local/lib/python3.10/site-packages/django/conf/__init__.py", line 71, in _setup
    self._wrapped = Settings(settings_module)
  File "/usr/local/lib/python3.10/site-packages/django/conf/__init__.py", line 179, in __init__
    mod = importlib.import_module(self.SETTINGS_MODULE)
  File "/usr/local/lib/python3.10/importlib/__init__.py", line 126, in import_module
    return _bootstrap._gcd_import(name[level:], package, level)
  File "<frozen importlib._bootstrap>", line 1050, in _gcd_import
  File "<frozen importlib._bootstrap>", line 1027, in _find_and_load
  File "<frozen importlib._bootstrap>", line 1006, in _find_and_load_unlocked
  File "<frozen importlib._bootstrap>", line 688, in _load_unlocked
  File "<frozen importlib._bootstrap_external>", line 883, in exec_module
  File "<frozen importlib._bootstrap>", line 241, in _call_with_frames_removed
  File "/app/SilthsSanctuary/settings/local.py", line 1, in <module>
    from base import *
ModuleNotFoundError: No module named 'base'
[2022-02-04 10:05:11 +0000] [13] [INFO] Worker exiting (pid: 13)
[2022-02-04 10:05:11 +0000] [14] [ERROR] Exception in worker process
Traceback (most recent call last):
  File "/usr/local/lib/python3.10/site-packages/gunicorn/arbiter.py", line 589, in spawn_worker
    worker.init_process()
  File "/usr/local/lib/python3.10/site-packages/gunicorn/workers/base.py", line 134, in init_process
    self.load_wsgi()
  File "/usr/local/lib/python3.10/site-packages/gunicorn/workers/base.py", line 146, in load_wsgi
    self.wsgi = self.app.wsgi()
  File "/usr/local/lib/python3.10/site-packages/gunicorn/app/base.py", line 67, in wsgi
    self.callable = self.load()
  File "/usr/local/lib/python3.10/site-packages/gunicorn/app/wsgiapp.py", line 58, in load
    return self.load_wsgiapp()
  File "/usr/local/lib/python3.10/site-packages/gunicorn/app/wsgiapp.py", line 48, in load_wsgiapp
    return util.import_app(self.app_uri)
  File "/usr/local/lib/python3.10/site-packages/gunicorn/util.py", line 359, in import_app
    mod = importlib.import_module(module)
  File "/usr/local/lib/python3.10/importlib/__init__.py", line 126, in import_module
    return _bootstrap._gcd_import(name[level:], package, level)
  File "<frozen importlib._bootstrap>", line 1050, in _gcd_import
  File "<frozen importlib._bootstrap>", line 1027, in _find_and_load
  File "<frozen importlib._bootstrap>", line 1006, in _find_and_load_unlocked
  File "<frozen importlib._bootstrap>", line 688, in _load_unlocked
  File "<frozen importlib._bootstrap_external>", line 883, in exec_module
  File "<frozen importlib._bootstrap>", line 241, in _call_with_frames_removed
  File "/app/SilthsSanctuary/wsgi.py", line 15, in <module>
    application = get_wsgi_application()
  File "/usr/local/lib/python3.10/site-packages/django/core/wsgi.py", line 12, in get_wsgi_application
    django.setup(set_prefix=False)
  File "/usr/local/lib/python3.10/site-packages/django/__init__.py", line 19, in setup
    configure_logging(settings.LOGGING_CONFIG, settings.LOGGING)
  File "/usr/local/lib/python3.10/site-packages/django/conf/__init__.py", line 84, in __getattr__
    self._setup(name)
  File "/usr/local/lib/python3.10/site-packages/django/conf/__init__.py", line 71, in _setup
    self._wrapped = Settings(settings_module)
  File "/usr/local/lib/python3.10/site-packages/django/conf/__init__.py", line 179, in __init__
    mod = importlib.import_module(self.SETTINGS_MODULE)
  File "/usr/local/lib/python3.10/importlib/__init__.py", line 126, in import_module
    return _bootstrap._gcd_import(name[level:], package, level)
  File "<frozen importlib._bootstrap>", line 1050, in _gcd_import
  File "<frozen importlib._bootstrap>", line 1027, in _find_and_load
  File "<frozen importlib._bootstrap>", line 1006, in _find_and_load_unlocked
  File "<frozen importlib._bootstrap>", line 688, in _load_unlocked
  File "<frozen importlib._bootstrap_external>", line 883, in exec_module
  File "<frozen importlib._bootstrap>", line 241, in _call_with_frames_removed
  File "/app/SilthsSanctuary/settings/local.py", line 1, in <module>
    from base import *
ModuleNotFoundError: No module named 'base'
[2022-02-04 10:05:11 +0000] [14] [INFO] Worker exiting (pid: 14)
[2022-02-04 10:05:11 +0000] [15] [ERROR] Exception in worker process
Traceback (most recent call last):
  File "/usr/local/lib/python3.10/site-packages/gunicorn/arbiter.py", line 589, in spawn_worker
    worker.init_process()
  File "/usr/local/lib/python3.10/site-packages/gunicorn/workers/base.py", line 134, in init_process
    self.load_wsgi()
  File "/usr/local/lib/python3.10/site-packages/gunicorn/workers/base.py", line 146, in load_wsgi
    self.wsgi = self.app.wsgi()
  File "/usr/local/lib/python3.10/site-packages/gunicorn/app/base.py", line 67, in wsgi
    self.callable = self.load()
  File "/usr/local/lib/python3.10/site-packages/gunicorn/app/wsgiapp.py", line 58, in load
    return self.load_wsgiapp()
  File "/usr/local/lib/python3.10/site-packages/gunicorn/app/wsgiapp.py", line 48, in load_wsgiapp
    return util.import_app(self.app_uri)
  File "/usr/local/lib/python3.10/site-packages/gunicorn/util.py", line 359, in import_app
    mod = importlib.import_module(module)
  File "/usr/local/lib/python3.10/importlib/__init__.py", line 126, in import_module
    return _bootstrap._gcd_import(name[level:], package, level)
  File "<frozen importlib._bootstrap>", line 1050, in _gcd_import
  File "<frozen importlib._bootstrap>", line 1027, in _find_and_load
  File "<frozen importlib._bootstrap>", line 1006, in _find_and_load_unlocked
  File "<frozen importlib._bootstrap>", line 688, in _load_unlocked
  File "<frozen importlib._bootstrap_external>", line 883, in exec_module
  File "<frozen importlib._bootstrap>", line 241, in _call_with_frames_removed
  File "/app/SilthsSanctuary/wsgi.py", line 15, in <module>
    application = get_wsgi_application()
  File "/usr/local/lib/python3.10/site-packages/django/core/wsgi.py", line 12, in get_wsgi_application
    django.setup(set_prefix=False)
  File "/usr/local/lib/python3.10/site-packages/django/__init__.py", line 19, in setup
    configure_logging(settings.LOGGING_CONFIG, settings.LOGGING)
  File "/usr/local/lib/python3.10/site-packages/django/conf/__init__.py", line 84, in __getattr__
    self._setup(name)
  File "/usr/local/lib/python3.10/site-packages/django/conf/__init__.py", line 71, in _setup
    self._wrapped = Settings(settings_module)
  File "/usr/local/lib/python3.10/site-packages/django/conf/__init__.py", line 179, in __init__
    mod = importlib.import_module(self.SETTINGS_MODULE)
  File "/usr/local/lib/python3.10/importlib/__init__.py", line 126, in import_module
    return _bootstrap._gcd_import(name[level:], package, level)
  File "<frozen importlib._bootstrap>", line 1050, in _gcd_import
  File "<frozen importlib._bootstrap>", line 1027, in _find_and_load
  File "<frozen importlib._bootstrap>", line 1006, in _find_and_load_unlocked
  File "<frozen importlib._bootstrap>", line 688, in _load_unlocked
  File "<frozen importlib._bootstrap_external>", line 883, in exec_module
  File "<frozen importlib._bootstrap>", line 241, in _call_with_frames_removed
  File "/app/SilthsSanctuary/settings/local.py", line 1, in <module>
    from base import *
ModuleNotFoundError: No module named 'base'
[2022-02-04 10:05:11 +0000] [15] [INFO] Worker exiting (pid: 15)
[2022-02-04 10:06:37 +0000] [1] [INFO] Starting gunicorn 20.1.0
[2022-02-04 10:06:37 +0000] [1] [INFO] Listening at: http://0.0.0.0:8000 (1)
[2022-02-04 10:06:37 +0000] [1] [INFO] Using worker: sync
[2022-02-04 10:06:37 +0000] [13] [INFO] Booting worker with pid: 13
[2022-02-04 10:06:37 +0000] [14] [INFO] Booting worker with pid: 14
[2022-02-04 10:06:37 +0000] [15] [INFO] Booting worker with pid: 15
[2022-02-04 10:06:37 +0000] [16] [INFO] Booting worker with pid: 16
